apps/sample1.csv
id,side,type,price,qty
1,S,LIMIT,101,10
2,S,LIMIT,102,5
3,B,LIMIT,99,8
4,B,LIMIT,100,4
5,B,LIMIT,101,6
6,B,MARKET,0,8
7,S,IOC,100,10
8,S,FOK,99,8
9,S,FOK,90,100
10,S,LIMIT,103,5
11,S,LIMIT,102,4
12,B,LIMIT,102,3
13,B,MARKET,0,10
14,B,LIMIT,98,5
15,B,LIMIT,98,5
16,B,LIMIT,97,5
17,S,IOC,98,8
18,S,FOK,97,7
19,B,MARKET,0,5
20,S,FOK,100,1
