apps/sample2.csv
id,side,type,price,qty
1,S,LIMIT,105,10
2,S,LIMIT,106,10
3,S,LIMIT,107,10
4,S,LIMIT,108,10
5,B,LIMIT,104,10
6,B,LIMIT,103,10
7,B,LIMIT,102,10
8,B,LIMIT,101,10
9,B,LIMIT,107,25
10,B,MARKET,0,15
11,S,LIMIT,100,35
12,S,MARKET,0,5
13,S,MARKET,0,5
