apps/sample3.csv
id,side,type,price,qty
1,B,LIMIT,100,10
2,S,LIMIT,100,10
3,B,LIMIT,100,5
4,S,FOK,100,6
5,S,FOK,100,5
6,B,IOC,99,5
7,S,LIMIT,98,10
8,B,IOC,98,4
9,B,LIMIT,99,3
10,B,LIMIT,97,5
11,B,MARKET,0,3
12,S,FOK,98,5
13,S,FOK,97,5
